Workbook

Sheet Embodied Carbon Factors
A1: material/component | B1: region | C1: unit | D1: kg CO2e/unit | E1: st dev | F1: source | G1: modules | H1: notes | I1: electricity share | J1: thermal energy share
A2: Ready-mix concrete | B2: Europe | C2: m3 | D2: 271 | E2: 52.574 | F2: EC3 | G2: A1-A3 | H2: 2400 kg/m3 | I2: 0.1 | J2: 0.65
A3: Steel rebars | B3: Europe | C3: kg | D3: 0.869 | E3: 0.5677 | F3: EC3 | G3: A1-A3 | H3: - | I3: 0.1 | J3: 0.8
A4: Hot-rolled steel sections | B4: Europe | C4: kg | D4: 0.69332 | E4: 0.25037 | F4: EC3 | G4: A1-A3 | H4: - | I4: 0.1 | J4: 0.8
A5: Cold-formed steel sections | B5: Europe | C5: kg | D5: 2.52 | E5: 0.55 | F5: EC3 | G5: A1-A3 | H5: - | I5: 0.1 | J5: 0.8
A6: Steel decking | B6: Europe | C6: kg | D6: 2.99 | E6: 0.58903 | F6: EC3 | G6: A1-A3 | H6: - | I6: 0.1 | J6: 0.8
A7: Mass timber | B7: Europe | C7: m3 | D7: 162 | E7: 108.378 | F7: EC3 | G7: A1-A3 | H7: 640 kg/m3 | I7: 0.45 | J7: 0.3
A8: Nonstructural wood | B8: Europe | C8: m3 | D8: 175 | E8: 71.9 | F8: EC3 | G8: A1-A3 | H8: - | I8: 0.45 | J8: 0.3
A9: Hollow clay bricks | B9: Europe | C9: kg | D9: 0.2 | E9: 0.06766 | F9: Asdrubali et al. (2023) | G9: A1-A3 | H9: 400-1604 kg/m3 | I9: 0.1 | J9: 0.8
A10: Solid clay bricks | B10: Europe | C10: kg | D10: 0.2 | E10: 0.07517 | F10: Asdrubali et al. (2023) | G10: A1-A3 | H10: 600-2300 kg/m3 | I10: 0.1 | J10: 0.8
A11: Hollow concrete blocks | B11: Europe | C11: kg | D11: 0.23 | E11: 0.0996 | F11: Asdrubali et al. (2023) | G11: A1-A3 | H11: 115-2245kg/m3 | I11: 0.1 | J11: 0.65
A12: Solid concrete blocks | B12: =B11 -> Europe | C12: =C11 -> kg | D12: =D11 -> 0.23 | E12: =E11 -> 0.0996 | F12: =F11 -> Asdrubali et al. (2023) | G12: =G11 -> A1-A3 | H12: =H11 -> 115-2245kg/m3 | I12: 0.1 | J12: 0.65
A13: Sandstone bricks | B13: Europe | C13: kg | D13: 0.13 | E13: 0.0748 | F13: Asdrubali et al. (2023) | G13: A1-A3 | H13: 1450-2570 kg/m3 | I13: 0.05 | J13: 0.15
A14: Granite | B14: United Kingdom | C14: kg | D14: 0.093 | E14: 0 | F14: Crishna et al. (2011) | G14: A1-A3 | H14: 2700 kg/m3 | I14: 0.05 | J14: 0.15
A15: Adobe bricks | B15: Cyprus | C15: kg | D15: 0.0017 | E15: 0 | F15: Christoforou et al. (2016) | G15: A1-A4 | H15: Scenario 4 (on the building site using locally available soil and transported sawdust (50 km)) 0.0017 kg/kg, assuming sawdust with density equal to 1,500 kg/m3. | I15: 0.05 | J15: 0.15
A16: Rammed earth | B16: Portugal | C16: kg | D16: ='EU-Earthen materials'!J12 -> 0.024385 | E16: ='EU-Earthen materials'!J13 -> 0.00086974134 | F16: Manual collection | G16: A1-A5 | H16: 2000 kg/m3 | I16: 0.05 | J16: 0.15
A17: Compressed earth blocks | B17: Portugal | C17: kg | D17: ='EU-Earthen materials'!J3 -> 0.059100529 | E17: ='EU-Earthen materials'!J4 -> 0.0045848935 | F17: Manual collection | G17: A1-A3 | H17: 2000 kg/m3 | I17: 0.05 | J17: 0.15
A18: Aluminum window frame, double glazing | B18: Europe | C18: m2 | D18: 105 | E18: 21.15 | F18: Asdrubali et al. (2021) | G18: A1-A3 | H18: Average value | I18: =0.4*0.6+0.6*0.35 -> 0.45 | J18: =0.4*0.25+0.6*0.55 -> 0.43
A19: Aluminum window frame, triple glazing | B19: Europe | C19: m2 | D19: 141.9 | E19: 57.61 | F19: Asdrubali et al. (2021) | G19: A1-A3 | H19: Average value | I19: =0.4*0.6+0.6*0.35 -> 0.45 | J19: =0.4*0.25+0.6*0.55 -> 0.43
A20: Wooden window frame, double glazing | B20: Europe | C20: m2 | D20: 55 | E20: 25.495 | F20: Asdrubali et al. (2021) | G20: A1-A3 | H20: Average value | I20: =0.4*0.45+0.6*0.35 -> 0.39 | J20: =0.4*0.3+0.6*0.55 -> 0.45
A21: Wooden window frame, triple glazing | B21: Europe | C21: m2 | D21: 53.6 | E21: 20.28 | F21: Asdrubali et al. (2021) | G21: A1-A3 | H21: Average value | I21: =0.4*0.45+0.6*0.35 -> 0.39 | J21: =0.4*0.3+0.6*0.55 -> 0.45
A22: PVC window frame, double glazing | B22: Europe | C22: m2 | D22: 68.4 | E22: 14.44 | F22: Asdrubali et al. (2021) | G22: A1-A3 | H22: Average value | I22: =0.4*0.25+0.6*0.35 -> 0.31 | J22: =0.4*0.5+0.6*0.55 -> 0.53
A23: PVC window frame, triple glazing | B23: Europe | C23: m2 | D23: 100.5 | E23: 48.05 | F23: Asdrubali et al. (2021) | G23: A1-A3 | H23: Average value | I23: =0.4*0.25+0.6*0.35 -> 0.31 | J23: =0.4*0.5+0.6*0.55 -> 0.53
A24: Steel window frame, double glazing | B24: Europe | C24: m2 | D24: 127.3 | E24: 35.567 | F24: Asdrubali et al. (2021) | G24: A1-A3 | H24: Average value | I24: =0.4*0.1+0.6*0.35 -> 0.25 | J24: 0.8
A25: Steel window frame, triple glazing | B25: Europe | C25: m2 | D25: 168.8 | E25: 76.42 | F25: Asdrubali et al. (2021) | G25: A1-A3 | H25: Average value | I25: =0.4*0.1+0.6*0.35 -> 0.25 | J25: 0.8
A26: Ceramic tiles | B26: Europe | C26: m2 | D26: 12.1 | E26: 4.05 | F26: EC3 | G26: A1-A3 | H26: 18 kg/m2 | I26: 0.1 | J26: 0.8
A27: Gypsum boards | B27: Europe | C27: m2 | D27: 2.24 | E27: 1.29 | F27: EC3 | G27: A1-A3 | H27: 20 kg/m2 | I27: 0.2 | J27: 0.6
A28: Mineral wool | B28: Europe | C28: m2 | D28: 3.51 | E28: 2.21 | F28: EC3 | G28: A1-A3 | H28: 80 kg/m3 | I28: 0.4 | J28: 0.5
A29: Cement | B29: Europe | C29: ton | D29: 789 | E29: 143 | F29: EC3 | G29: A1-A3 | H29: - | I29: 0.15 | J29: 0.75
A30: Sand | B30: Europe | C30: ton | D30: 63.32 | E30: 19.62 | F30: ICE | G30: A1-A3 | H30: - | I30: 0.05 | J30: 0.1
A31: Marble | B31: Europe | C31: kg | D31: 0.13 | E31: 0 | F31: ICE | G31: A1-A3 | H31: - | I31: 0.35 | J31: 0.55
A32: Bituminous roof membrane | B32: Europe | C32: m2 | D32: 5.32 | E32: 2.99 | F32: EC3 | G32: A1-A3 | H32: 5 kg/m2 | I32: 0.2 | J32: 0.7
A33: Metal ceilings (lay in tile) | B33: Europe | C33: m2 | D33: ='EU-Lay in tile ceilings'!L3 -> 20.108447 | E33: ='EU-Lay in tile ceilings'!L4 -> 7.0161267 | F33: Manual collection | G33: A1-A3 | H33: 8 kg/m2 | I33: 0.1 | J33: 0.8
A34: Raised access floor | B34: Europe | C34: m2 | D34: ='EU-Raised access floors'!L3 -> 21.6 | E34: ='EU-Raised access floors'!L4 -> 12.727922 | F34: Manual collection | G34: A1-A3 | H34: 8 kg/m2 | I34: 0.1 | J34: 0.8
A35: Plastic pipes | B35: Europe | C35: kg | D35: ='EU-Piping'!M3 -> 2.7279607 | E35: ='EU-Piping'!M4 -> 2.2174432 | F35: Manual collection | G35: A1-A3 | H35: - | I35: 0.25 | J35: 0.5
A36: Elevators (RES) | B36: Europe | C36: unit | D36: ='EU-Elevators'!S3 -> 10046.482 | E36: ='EU-Elevators'!S4 -> 3060.4596 | F36: Manual collection | G36: A1-A3 | H36: - | I36: 0.4 | J36: 0.3
A37: Elevators (COM/IND) | B37: Europe | C37: unit | D37: ='EU-Elevators'!S7 -> 56468.179 | E37: ='EU-Elevators'!S8 -> 27957.833 | F37: Manual collection | G37: A1-A3 | H37: - | I37: 0.4 | J37: 0.3
A38: HVAC | B38: Europe | C38: m2 built area | D38: ='EU-HVAC'!K3 -> 35.121724 | E38: ='EU-HVAC'!K4 -> 17.176351 | F38: Manual collection | G38: A1-A3 | H38: - | I38: 0.45 | J38: 0.35
A39: Electrical system | B39: Europe | C39: m2 built area | D39: ='EU-Electrical system'!J3 -> 9.9760303 | E39: ='EU-Electrical system'!J4 -> 4.702566 | F39: Manual collection | G39: A1-A3 | H39: - | I39: 0.5 | J39: 0.25
A40: Fire system | B40: Europe | C40: m2 built area | D40: ='EU-Fire system'!J3 -> 4.9858757 | E40: ='EU-Fire system'!J4 -> 1.0002992 | F40: Manual collection | G40: A1-A3 | H40: - | I40: 0.35 | J40: 0.4

Sheet Module A1-A3
A1: component | B1: description | C1: unit | D1: kg CO2e/unit | E1: st dev | F1: kg/unit | G1: waste rate | I1: materials | J1: density (kg/m3)
A2: RC beam | B2: 225 kg of steel per cubic meter (2.86% volumetric ratio) | C2: m3 | D2: =225*'Embodied Carbon Factors'!D3 + 0.9714*'Embodied Carbon Factors'!D2 -> 458.7744 | E2: =SQRT((225*'Embodied Carbon Factors'!E3)^2 + (0.9714*'Embodied Carbon Factors'!E2)^2) -> 137.56371 | F2: =0.9714*J2 + (1-0.9714)*J3 -> 2555.87 | G2: 0.05 | I2: concrete (unreinf) | J2: 2400
A3: RC column | B3: 325 kg of steel per cubic meter (4.14% volumetric ratio) | C3: m3 | D3: =325*'Embodied Carbon Factors'!D3 + 0.9586*'Embodied Carbon Factors'!D2 -> 542.2056 | E3: =SQRT((325*'Embodied Carbon Factors'!E3)^2 + (0.9586*'Embodied Carbon Factors'!E2)^2) -> 191.26179 | F3: =0.9586*J2 + (1-0.9586)*J3 -> 2625.63 | G3: 0.05 | I3: steel | J3: 7850
A4: RC frame | B4: 1/3 columns and 2/3 beams | C4: m3 | D4: =0.67*D2 + 0.33*D3 -> 486.3067 | E4: =0.67*E2 + 0.33*E3 -> 155.28408 | F4: =0.67*F2 + 0.33*F3 -> 2578.8908 | G4: 0.05 | I4: solid clay | J4: 1700
A5: RC foundation | B5: 85 kg of steel per cubic meter (1.08% volumetric ratio) | C5: m3 | D5: =85*'Embodied Carbon Factors'!D3 + 0.9892*'Embodied Carbon Factors'!D2 -> 341.9382 | E5: =SQRT((85*'Embodied Carbon Factors'!E3)^2 + (0.9892*'Embodied Carbon Factors'!E2)^2) -> 70.944638 | F5: =0.9892*J2 + (1-0.9892)*J3 -> 2458.86 | G5: 0.05 | I5: hollow clay | J5: 1300
A6: RC wall | B6: 125 kg of steel per cubic meter (1.59% volumetric ratio) | C6: m3 | D6: =125*'Embodied Carbon Factors'!D3 + 0.9841*'Embodied Carbon Factors'!D2 -> 375.3161 | E6: =SQRT((125*'Embodied Carbon Factors'!E3)^2 + (0.9841*'Embodied Carbon Factors'!E2)^2) -> 87.820867 | F6: =0.9841*J2 + (1-0.9841)*J3 -> 2486.655 | G6: 0.05 | I6: hollow clay (slab) | J6: 500
A7: RC solid slab | B7: 110 kg of steel per cubic meter (1.4% volumetric ratio) | C7: m3 | D7: =110*'Embodied Carbon Factors'!D3 + 0.986*'Embodied Carbon Factors'!D2 -> 362.796 | E7: =SQRT((110*'Embodied Carbon Factors'!E3)^2 + (0.986*'Embodied Carbon Factors'!E2)^2) -> 81.159117 | F7: =0.986*J2 + (1-0.986)*J3 -> 2476.3 | G7: 0.05 | I7: hollow concrete | J7: 1500
A8: RC ribbed slab (with hollow clay bricks) | B8: 90 kg of steel per cubic meter (1.15% volumetric ratio) and 40x40x17 cm hollow clay blocks with density 500 kg/m3 (36%), 8 cm flange and 15 cm web, slab height 0.25 m | C8: m3 | D8: =(90*(0.55*0.55*0.25-0.4*0.4*0.17)*'Embodied Carbon Factors'!D3 + 0.9885*(0.55*0.55*0.25-0.4*0.4*0.17)*'Embodied Carbon Factors'!D2 + (0.4*0.4*0.17)*'Embodied Carbon Factors'!D9*J6)/0.25/0.55/0.55 -> 257.58119 | E8: =SQRT((90*(0.55*0.55*0.25-0.4*0.4*0.17)*'Embodied Carbon Factors'!E3)^2 + (0.9885*(0.55*0.55*0.25-0.4*0.4*0.17)*'Embodied Carbon Factors'!E2)^2 + ((0.4*0.4*0.17)*'Embodied Carbon Factors'!E9*J6)^2)/0.25/0.55/0.55 -> 48.226681 | F8: =((1-0.9885)*(0.55*0.55*0.25-0.4*0.4*0.17)*J3 + 0.9885*(0.55*0.55*0.25-0.4*0.4*0.17)*J2 + (0.4*0.4*0.17)*J6)/0.25/0.55/0.55 -> 1756.7608 | G8: 0.06 | I8: timber | J8: 640
A9: RC ribbed slab (with hollow concrete blocks) | B9: 90 kg of steel per cubic meter (1.15% volumetric ratio) and 40x40x17 cm hollow concrete blocks with density 1500 kg/m3 (36%), 8 cm flange and 15 cm web, slab height 0.25 m | C9: m3 | D9: =(90*(0.55*0.55*0.25-0.4*0.4*0.17)*'Embodied Carbon Factors'!D3 + 0.9885*(0.55*0.55*0.25-0.4*0.4*0.17)*'Embodied Carbon Factors'!D2 + (0.4*0.4*0.17)*'Embodied Carbon Factors'!D11*J7)/0.25/0.55/0.55 -> 345.7002 | E9: =SQRT((90*(0.55*0.55*0.25-0.4*0.4*0.17)*'Embodied Carbon Factors'!E3)^2 + (0.9885*(0.55*0.55*0.25-0.4*0.4*0.17)*'Embodied Carbon Factors'!E2)^2 + ((0.4*0.4*0.17)*'Embodied Carbon Factors'!E11*J7)^2)/0.25/0.55/0.55 -> 71.17001 | F9: =((1-0.9885)*(0.55*0.55*0.25-0.4*0.4*0.17)*J3 + 0.9885*(0.55*0.55*0.25-0.4*0.4*0.17)*J2 + (0.4*0.4*0.17)*J7)/0.25/0.55/0.55 -> 2116.4302 | G9: 0.05 | I9: gypsum | J9: 1000
A10: RC and steel composite floor | B10: 90 kg of steel per cubic meter (1.15% volumetric ratio), 15 cm solid slab, 7610 mm2 girders with 2 m spacing, steel deck with depth of 80 mm, openings spaced by 120 mm with 120 mm width [each 1 m of slab will have 3.333 parts of deck] | C10: m3 | D10: =(7610*10^-6*J3*'Embodied Carbon Factors'!D4 + (0.15*2-3.33*0.18*0.08)*'Embodied Carbon Factors'!D2 + 90*(0.15*2-3.33*0.18*0.08)*'Embodied Carbon Factors'!D3 + 3.33*0.001*(0.18+0.06+0.06)*J3*'Embodied Carbon Factors'!D6)/(0.15*2+7610*10^-6) -> 497.00467 | E10: =SQRT((7610*10^-6*J3*'Embodied Carbon Factors'!E4)^2 + ((0.15*2-3.33*0.18*0.08)*'Embodied Carbon Factors'!E2)^2 + (90*(0.15*2-3.33*0.18*0.08)*'Embodied Carbon Factors'!E3)^2 + (3.33*0.001*(0.18+0.06+0.06)*J3*'Embodied Carbon Factors'!E6)^2)/(0.15*2+7610*10^-6) -> 78.727099 | F10: =(7610*10^-6*J3+(0.15*2-3.33*0.18*0.08)*J2 + 90*(0.15*2-3.33*0.18*0.08) + 3.33*0.001*(0.18+0.06+0.06)*J3)/(0.15*2+7610*10^-6) -> 2259.9401 | G10: 0.05 | I10: stone wool | J10: 80
A11: Timber floor | B11: timber joist 30x5 cm spaced at 0.6 m one way, timber slab 2 cm thick, 0.045 m3/m2 | C11: m3 | D11: ='Embodied Carbon Factors'!D7 -> 162 | E11: ='Embodied Carbon Factors'!E7 -> 108.378 | F11: =J8 -> 640 | G11: 0.1 | I11: mortar | J11: 2100
A12: RC and timber composite floor | B12: timber joist 30x5 cm spaced at 0.6 m one way (34% volumetric ratio), solid RC slab of 5 cm thickness (66% volumetric ratio), 90 kg of steel per cubic meter (1.15% volumetric ratio), 0.075 m3/m2 | C12: m3 | D12: =(0.9885*0.6*0.05*'Embodied Carbon Factors'!D2 + 90*0.6*0.05*'Embodied Carbon Factors'!D3 + 0.3*0.05*'Embodied Carbon Factors'!D7)/(0.05*0.6 + 0.3*0.05) -> 284.729 | E12: =SQRT((0.9885*0.6*0.05*'Embodied Carbon Factors'!E2)^2 + (90*0.6*0.05*'Embodied Carbon Factors'!E3)^2 + (0.3*0.05*'Embodied Carbon Factors'!E7)^2)/(0.05*0.6 + 0.3*0.05) -> 60.544789 | F12: =(0.9885*0.6*0.05*J2 + (1-0.9885)*0.6*0.05*J3 + 0.3*0.05*J8)/(0.05*0.6 + 0.3*0.05) -> 1855.1167 | G12: 0.1 | I12: plaster | J12: 800
A13: Timber structural components | B13: applicable to walls and to frames | C13: m3 | D13: ='Embodied Carbon Factors'!D7 -> 162 | E13: ='Embodied Carbon Factors'!E7 -> 108.378 | F13: =J8 -> 640 | G13: 0.02 | I13: granite | J13: 2700
A14: Cold formed steel members | B14: density 7850 kg/m3 | C14: m3 | D14: ='Embodied Carbon Factors'!D5*J3 -> 19782 | E14: ='Embodied Carbon Factors'!E5*J3 -> 4317.5 | F14: =J3 -> 7850 | G14: 0.01
A15: Hot rolled steel members | B15: density 7850 kg/m3 | C15: m3 | D15: ='Embodied Carbon Factors'!D4*J3 -> 5442.562 | E15: ='Embodied Carbon Factors'!E4*J3 -> 1965.4045 | F15: =J3 -> 7850 | G15: 0.01
A16: Solid clay infill (external) | B16: density 1700 kg/m3, brick 25x25 cm, panel 3x4.5 m, 25 cm thick, mortar (2100 kgm3) within 1 cm joints (1/4 ratio), plaster of 3 cm thick (800 kg/m3) (1/6 ratio), two-layer stone wool insulation | C16: m | D16: 384.50559 | E16: 98.241071 | F16: =(J4*0.25*0.25*0.25 + (0.26*0.26-0.25*0.25)*0.25*J11 + 0.26*0.26*0.03*2*J12 + 0.26*0.26*0.025*2*J10)/0.26/0.26*3 -> 1453.6331 | G16: 0.06
A17: Hollow clay infill (external) | B17: density 1300 kg/m3, brick 25x25 cm, panel 3x4.5 m, 25 cm thick, mortar (2100 kgm3) within 1 cm joints (1/4 ratio), plaster of 3 cm thick (800 kg/m3) (1/6 ratio), two-layer stone wool insulation | C17: m | D17: 324.46572 | E17: 69.461051 | F17: =(J5*0.25*0.25*0.25 + (0.26*0.26-0.25*0.25)*0.25*J11 + 0.26*0.26*0.03*2*J12 + 0.26*0.26*0.025*2*J10)/0.26/0.26*3 -> 1176.2663 | G17: 0.06
A18: Hollow concrete infill (external) | B18: density 1500 kg/m3, brick 25x25 cm, panel 3x4.5 m, 25 cm thick, mortar (2100 kgm3) within 1 cm joints (1/4 ratio), plaster of 3 cm thick (800 kg/m3) (1/6 ratio), two-layer stone wool insulation | C18: m | D18: 388.45986 | E18: 114.11491 | F18: =(J7*0.25*0.25*0.25 + (0.26*0.26-0.25*0.25)*0.25*J11 + 0.26*0.26*0.03*2*J12 + 0.26*0.26*0.025*2*J10)/0.26/0.26*3 -> 1314.9497 | G18: 0.05
A19: Solid clay infill (internal) | B19: density 1700 kg/m3, brick 25x25 cm, panel 3x4.5 m, 10 cm thick, mortar (2100 kgm3) within 1 cm joints (1/4 ratio), plaster of 3 cm thick (800 kg/m3) (1/6 ratio) | C19: m | D19: 193.61598 | E19: 40.983258 | F19: =(J4*0.25*0.25*0.1 + (0.26*0.26-0.25*0.25)*0.1*J11 + 0.26*0.26*0.03*2*J12)/0.26/0.26*3 -> 663.05325 | G19: 0.06
A20: Hollow clay infill (internal) | B20: density 1300 kg/m3, brick 25x25 cm, panel 3x4.5 m, 10 cm thick, mortar (2100 kgm3) within 1 cm joints (1/4 ratio), plaster of 3 cm thick (800 kg/m3) (1/6 ratio) | C20: m | D20: 169.60003 | E20: 30.138221 | F20: =(J5*0.25*0.25*0.1 + (0.26*0.26-0.25*0.25)*0.1*J11 + 0.26*0.26*0.03*2*J12)/0.26/0.26*3 -> 552.10651 | G20: 0.06
A21: Hollow concrete infill (internal) | B21: density 1500 kg/m3, brick 25x25 cm, panel 3x4.5 m, 10 cm thick, mortar (2100 kgm3) within 1 cm joints (1/4 ratio), plaster of 3 cm thick (800 kg/m3) (1/6 ratio) | C21: m | D21: 195.19768 | E21: 47.099084 | F21: =(J7*0.25*0.25*0.1 + (0.26*0.26-0.25*0.25)*0.1*J11 + 0.26*0.26*0.03*2*J12)/0.26/0.26*3 -> 607.57988 | G21: 0.05
A22: Unreinforced masonry wall (with solid clay bricks) | B22: density 1700 kg/m3, brick 25x25 cm, panel 3x4.5 m, 30 cm thick, plaster of 3 cm thick (800 kg/m3) (1/6 ratio), mortar (2100 kgm3) within 1 cm joints (1/4 ratio), two-layer stone wool insulation | C22: m3 | D22: 483.1262 | E22: 129.90314 | F22: =(J4*0.25*0.25*0.3 + (0.26*0.26-0.25*0.25)*0.3*J11 + 0.26*0.26*0.03*2*J12 + 0.26*0.26*0.025*2*J10)/0.26/0.26/(0.3+2*0.03+2*0.025) -> 1392.8128 | G22: 0.06
A23: Unreinforced masonry wall (with hollow clay bricks) | B23: density 1300 kg/m3, brick 25x25 cm, panel 3x4.5 m, 30 cm thick, plaster of 3 cm thick (800 kg/m3) (1/6 ratio), mortar (2100 kgm3) within 1 cm joints (1/4 ratio), two-layer stone wool insulation | C23: m3 | D23: 403.07305 | E23: 91.08465 | F23: =(J5*0.25*0.25*0.3 + (0.26*0.26-0.25*0.25)*0.3*J11 + 0.26*0.26*0.03*2*J12 + 0.26*0.26*0.025*2*J10)/0.26/0.26/(0.3+2*0.03+2*0.025) -> 1122.211 | G23: 0.06
A24: Reinforced masonry wall (with hollow concrete blocks) | B24: one vertical bar (16 mm) for each brick, two horizontal bars (12 mm) for every other joint, thickess 30 cm, 20% void filled by concrete, plaster of 3 cm thick (800 kg/m3) (1/6 ratio), mortar (2100 kgm3) within 1 cm joints (1/4 ratio), two-layer stone wool insulation, 70% external walls + 30% internal walls | C24: m3 | D24: 571.17004 | E24: 152.71754 | F24: =0.7 * (((J7*0.25*0.25*0.3 + (0.26*0.26-0.25*0.25)*0.3*J11 + 0.26*0.26*0.03*2*J12 + 0.25*0.3*0.25*0.2*J2 + (201*0.26+113*0.26)*10^-6*J3 + 0.26*0.26*0.025*2*J10))/0.26/0.26/(0.3+2*0.03+2*0.025)) + 0.3 * (((J7*0.25*0.25*0.3 + (0.26*0.26-0.25*0.25)*0.3*J11 + 0.26*0.26*0.03*2*J12 + 0.25*0.3*0.25*0.2*J2 + (201*0.26+113*0.26)*10^-6*J3))/0.26/0.26/(0.3+2*0.03)) -> 1668.9135 | G24: 0.06
A25: Reinforced masonry wall (with hollow clay bricks) | B25: one vertical bar (16 mm) for each brick, two horizontal bars (12 mm) for every other joint, thickess 30 cm, 20% void filled by concrete, plaster of 3 cm thick (800 kg/m3) (1/6 ratio), mortar (2100 kgm3) within 1 cm joints (1/4 ratio), two-layer stone wool insulation, 70% external walls + 30% internal walls | C25: m3 | D25: 485.84453 | E25: 93.595296 | F25: =0.7* ((J5*0.25*0.25*0.3 + (0.26*0.26-0.25*0.25)*0.3*J11 + 0.26*0.26*0.03*2*J12 + 0.25*0.3*0.25*0.2*J2 + (201*0.26+113*0.26)*10^-6*J3 + 0.26*0.26*0.025*2*J10)/0.26/0.26/(0.3+2*0.03+2*0.025)) + 0.3* ((J5*0.25*0.25*0.3 + (0.26*0.26-0.25*0.25)*0.3*J11 + 0.26*0.26*0.03*2*J12 + 0.25*0.3*0.25*0.2*J2 + (201*0.26+113*0.26)*10^-6*J3)/0.26/0.26/(0.3+2*0.03)) -> 1527.9751 | G25: 0.06
A26: Steel panels (Res) | B26: 10 cm solid clay bricks (with mortar included considering brick size 25*10*10 cm, assuming 1 m width fits 4 bricks given their size), 2 cm plasterboards, 15 cm studs (2 in 1 m) of 1 mm thickness and 30 cm length, 15 cm insulation layer (27 cm total thickness), 878 kg/m3, 3.25 m high | C26: m | D26: ='Embodied Carbon Factors'!D10*553 + 'Embodied Carbon Factors'!D27/(J9*0.02)*65 + 'Embodied Carbon Factors'!D5*15 + 'Embodied Carbon Factors'!D28*39/(0.15*J10) + 98/J11*(0.2*J11*'Embodied Carbon Factors'!D29*0.001 + 0.8*J11*'Embodied Carbon Factors'!D30*0.001) -> 187.51619 | E26: =SQRT(('Embodied Carbon Factors'!E10*553)^2 + ('Embodied Carbon Factors'!E27/(J9*0.02)*65)^2 + ('Embodied Carbon Factors'!E5*15)^2 + ('Embodied Carbon Factors'!E28*39/(0.15*J10))^2 + (98.28/J11*(0.2*J11*'Embodied Carbon Factors'!E29*0.001 + 0.8*J11*'Embodied Carbon Factors'!E30*0.001))^2)/1 -> 43.406942 | F26: 770 | G26: 0.06
A27: Steel panels (Com) | B27: 0.2 mm deck, 2 cm plasterboards, 15 cm studs (2 in 1 m) of 1 mm thickness and 30 cm length, 15 cm insulation layer (17 cm total thickness), 225 kg/m3, 4 m high | C27: m | D27: ='Embodied Carbon Factors'!D27/(J9*0.02)*80 + 'Embodied Carbon Factors'!D5*25 + 'Embodied Carbon Factors'!D28*48/(0.15*J10) -> 86 | E27: =SQRT(('Embodied Carbon Factors'!E27/(J9*0.02)*80)^2 + ('Embodied Carbon Factors'!E5*25)^2 + ('Embodied Carbon Factors'!E28*48/(0.15*J10))^2)/1 -> 17.141578 | F27: 153 | G27: 0.07
A28: Steel panels (Ind) | B28: 0.2 mm deck (2 layers), 10 cm insulation layer (10 cm total thickness), 111 kg/m3, 4 m high | C28: m | D28: ='Embodied Carbon Factors'!D28*32/(0.1*J10) + 'Embodied Carbon Factors'!D6*13 -> 52.91 | E28: =SQRT(('Embodied Carbon Factors'!E28*32/(0.1*J10))^2 + ('Embodied Carbon Factors'!E6*13)^2)/1 -> 11.69535 | F28: 45 | G28: 0.07
A29: Timber infills | B29: 1 cm timber panel, 2 cm plasterboards, 10 cm studs (2 in 1 m) of 1 mm thickness and 20 cm length, 10 cm insulation layer (13 cm total thickness), 289 kg/m3, 4 m high | C29: m | D29: ='Embodied Carbon Factors'!D8/J8*26 + 'Embodied Carbon Factors'!D27/(J9*0.02)*80 + 'Embodied Carbon Factors'!D5*13 + 'Embodied Carbon Factors'!D28*32/(0.1*J10) -> 62.869375 | E29: =SQRT(('Embodied Carbon Factors'!E8/J8*26)^2 + ('Embodied Carbon Factors'!E27/(J9*0.02)*80)^2 + ('Embodied Carbon Factors'!E5*13)^2 + ('Embodied Carbon Factors'!E28*32/(0.1*J10))^2)/1 -> 12.822854 | F29: 150 | G29: 0.1
A30: Timber partitions | B30: 1 cm timber panel, 2 cm plasterboards, 10 cm studs (2 in 1 m) of 1 mm thickness and 30 cm length (13 cm total thickness), 227 kg/m3, 4 m high | C30: m | D30: ='Embodied Carbon Factors'!D8/J8*26 + 'Embodied Carbon Factors'!D27/(J9*0.02)*80 + 'Embodied Carbon Factors'!D5*13 -> 48.829375 | E30: =SQRT(('Embodied Carbon Factors'!E8/J8*26)^2 + ('Embodied Carbon Factors'!E27/(J9*0.02)*80)^2 + ('Embodied Carbon Factors'!E5*13)^2)/1 -> 9.2887015 | F30: 118 | G30: 0.1
A31: Cladding (gross wall area) | B31: nonstructural timber panels, density 640 kg/m3, 2 cm thick | C31: m2 | D31: ='Embodied Carbon Factors'!D8*0.02 -> 3.5 | E31: ='Embodied Carbon Factors'!E8*0.02 -> 1.438 | F31: =J8*0.02 -> 12.8 | G31: 0.1
A32: Cladding (windows and glazing area) | B32: granite, 2700 kg/m3, 2 cm thick | C32: m2 | D32: ='Embodied Carbon Factors'!D14*J13*0.02 -> 5.022 | E32: ='Embodied Carbon Factors'!E14*J13*0.02 -> 0 | F32: =J13*0.02 -> 54 | G32: 0.05
A33: Doors (nonstructural wood) | B33: nonstructural timber panels, density 640 kg/m3, 2.1x0.9x0.05 m | C33: unit | D33: ='Embodied Carbon Factors'!D8*0.05*2.1*0.9 -> 16.5375 | E33: ='Embodied Carbon Factors'!E8*0.05*2.1*0.9 -> 6.79455 | F33: =J8*0.05*2.1*0.9 -> 60.48 | G33: 0.1
A34: Double-glazed windows with PVC frames | B34: weight 30 kg/m2, 60% glass, 40% PVC | C34: ='Embodied Carbon Factors'!C22 -> m2 | D34: ='Embodied Carbon Factors'!D22 -> 68.4 | E34: ='Embodied Carbon Factors'!E22 -> 14.44 | F34: =30 -> 30 | G34: 0.01
A35: Ceramic tile floors | C35: =C44 -> m2 | D35: =D44 -> 12.1 | E35: =E44 -> 4.05 | F35: =F44 -> 0 | G35: 0.06
A36: Raised access floors | B36: 8 kg/m2 | C36: m2 | D36: ='Embodied Carbon Factors'!D34 -> 21.6 | E36: ='Embodied Carbon Factors'!E34 -> 12.727922 | F36: 0 | G36: 0.01
A37: RC solid roofing | B37: =B7 -> 110 kg of steel per cubic meter (1.4% volumetric ratio) | C37: m2 | D37: =D7*0.15 -> 54.4194 | E37: =E7*0.15 -> 12.173868 | F37: =F7*0.15 -> 371.445 | G37: 0.05
A38: RC ribbed roofing (with hollow clay bricks) | B38: =B8 -> 90 kg of steel per cubic meter (1.15% volumetric ratio) and 40x40x17 cm hollow clay blocks with density 500 kg/m3 (36%), 8 cm flange and 15 cm web, slab height 0.25 m | C38: m2 | D38: =D8*0.25 -> 64.395298 | E38: =E8*0.25 -> 12.05667 | F38: =F8*0.25 -> 439.1902 | G38: 0.06
A39: RC ribbed roofing (with hollow concrete blocks) | B39: =B9 -> 90 kg of steel per cubic meter (1.15% volumetric ratio) and 40x40x17 cm hollow concrete blocks with density 1500 kg/m3 (36%), 8 cm flange and 15 cm web, slab height 0.25 m | C39: m2 | D39: =D9*0.25 -> 86.42505 | E39: =E9*0.25 -> 17.792503 | F39: =F9*0.25 -> 529.10756 | G39: 0.05
A40: RC and steel composite roofing | B40: =B10 -> 90 kg of steel per cubic meter (1.15% volumetric ratio), 15 cm solid slab, 7610 mm2 girders with 2 m spacing, steel deck with depth of 80 mm, openings spaced by 120 mm with 120 mm width [each 1 m of slab will have 3.333 parts of deck] | C40: m2 | D40: =(7610*10^-6*J3*'Embodied Carbon Factors'!D4 + (0.15*2-3.33*0.18*0.08)*'Embodied Carbon Factors'!D2 + 90*(0.15*2-3.33*0.18*0.08)*'Embodied Carbon Factors'!D3 + 3.33*0.001*(0.18+0.06+0.06)*7850*'Embodied Carbon Factors'!D6)/2 -> 76.441804 | E40: =SQRT((7610*10^-6*J3*'Embodied Carbon Factors'!E4)^2 + ((0.18*2-3.33*0.18*0.08)*'Embodied Carbon Factors'!E2)^2 + (90*(0.18*2-3.33*0.18*0.08)*'Embodied Carbon Factors'!E3)^2 + (3.33*0.001*(0.18+0.06+0.06)*7850*'Embodied Carbon Factors'!E6)^2)/(2) -> 13.85983 | F40: =(7610*10^-6*J3+(0.15*2-3.33*0.18*0.08)*J2+ 90*(0.15*2-3.33*0.18*0.08) + 3.33*0.001*(0.18+0.06+0.06)*J3)/(2) -> 347.59008 | G40: 0.05
...

Sheet Modules A4-A5
A1: module A4
A2: Distance (km) | C2: 120
A3: Load empy trucks (%) | C3: 70
A4: A4 factor (kgCO2e/t/km) | C4: 0.053
A5: A4 factor (kgCO2e/t) | C5: =C4*C2*(1+C3/100) -> 10.812
A7: module A5
A8: sub-module A5.1
A9: C1 | B9: 25% of sub-module A5.2 | C9: -
A10: C2 | B10: Distance (km) | C10: 50
B11: Load empy trucks (%) | C11: 50
B12: C2 factor (kgCO2e/t/km) | C12: =C4 -> 0.053
B13: C2 factor (kgCO2e/t) | C13: =C12*C10*(1+C11/100) -> 3.975
A14: C3-C4 | B14: Average rate of waste processing/disposal (kgCO2e/kg of waste) | C14: 0.013
B15: Percentage of materials to be landfilled (%) | C15: 0.1
B16: C3-C4 factor (kgCO2e/kg of waste) | C16: =C14*C15 -> 0.0013
A17: sub-module A5.2
A18: Diesel energy content (MJ/l) x carbon factor (kgCO2e/MJ) | C18: =38*0.073 -> 2.774
A19: sub-module A5.3
A20: Waste rate | B20: Reported per component in the previous sheet | C20: -

Sheet EU-Earthen materials
A1: COMPRESSED EARTH BLOCKS (CEB)
A2: source | B2: region | C2: unit | D2: modules | E2: kg CO2e/unit | F2: density (kg/m3) | G2: kg CO2e/kg | J2: embodied carbon | K2: unit
A3: Fernandes et al. (2019) | B3: Portugal | C3: unit | D3: A1-A3 | E3: 0.388 | F3: 2000 | G3: =E3/(0.3*0.15*0.07)/F3 -> 0.061587302 | I3: average | J3: =AVERAGE(G3:G5) -> 0.059100529 | K3: kgCO2e/kg
A4: Mateus et al. (2019) | B4: Portugal | C4: unit | D4: A1-A3 | E4: 0.39 | F4: 2000 | G4: =E4/(0.3*0.15*0.07)/F4 -> 0.061904762 | I4: stdev | J4: =STDEV(G3:G5) -> 0.0045848935 | K4: kgCO2e/kg
A5: Pereira et al. (2017) | B5: Portugal | C5: unit | D5: A1-A3 | E5: 0.339 | F5: 2000 | G5: =E5/(0.3*0.15*0.07)/F5 -> 0.053809524
A10: RAMMED EARTH
A11: source | B11: region | C11: unit | D11: modules | E11: kg CO2e/unit | F11: density (kg/m3) | G11: kg CO2e/kg | J11: embodied carbon | K11: unit
A12: Fernandes et al. (2019) | B12: Portugal | C12: m3 | D12: A1-A5 | E12: 47.54 | F12: 2000 | G12: =E12/F12 -> 0.02377 | I12: average | J12: =AVERAGE(G12:G13) -> 0.024385 | K12: kgCO2e/kg
A13: Mateus et al. (2019) | B13: Portugal | C13: m3 | D13: A1-A5 | E13: 50 | F13: 2000 | G13: =E13/F13 -> 0.025 | I13: stdev | J13: =STDEV(G12:G13) -> 0.00086974134 | K13: kgCO2e/kg

Sheet EU-Ceramic tiles
A1: CERAMIC WALL TILES
A2: source | B2: product | C2: website | D2: region | E2: modules | F2: unit | G2: kg CO2e/unit | H2: valid until | I2: notes | L2: embodied carbon | M2: unit
A3: AENOR | B3: Tiles | C3: https://www.en.aenor.com/Producto_DAP_pdf/GlobalEPD_002_043_ESP.pdf | D3: Spain | E3: A1-A3 | F3: m2 | G3: 8.13 | H3: 2024 | K3: average | L3: =AVERAGE(G3:G104) -> 11.881931 | M3: kgCO2e/m2
A4: AENOR | B4: Porcelain tiles | C4: https://www.en.aenor.com/Producto_DAP_pdf/DAP_Grespania_002-044%20BIa%20ENG.pdf | D4: Spain | E4: A1-A3 | F4: m2 | G4: 14 | H4: 2024 | K4: stdev | L4: =STDEV(G3:G104) -> 5.2895257 | M4: kgCO2e/m2
A5: AENOR | B5: Porous tiles | C5: https://www.en.aenor.com/Producto_DAP_pdf/DAP_Grespania_002-045%20BIII%20ENG.pdf | D5: Spain | E5: A1-A3 | F5: m2 | G5: 12.4 | H5: 2024
A6: AENOR | B6: Tile | C6: https://www.en.aenor.com/Producto_DAP_pdf/DAP%20ROCERSA_BIII_ENG.pdf | D6: Spain | E6: A1-A3 | F6: m2 | G6: 8.13 | H6: 2024
A7: AENOR | B7: Ceramic tiles, porcelain stoneware | C7: https://www.en.aenor.com/Producto_DAP_pdf/GlobalEPD_002_013_r1_ESP.pdf | D7: Spain | E7: A1-A3 | F7: m2 | G7: 9.63 | H7: 2025
A8: AENOR | B8: Ceramic tiles, glazed stoneware | C8: https://www.en.aenor.com/Producto_DAP_pdf/GlobalEPD_002_014_ESP.pdf | D8: Spain | E8: A1-A3 | F8: m2 | G8: 8.8 | H8: 2025
A9: AENOR | B9: Ceramic tiles, glazed stoneware | C9: https://www.en.aenor.com/Producto_DAP_pdf/GlobalEPD_002_015_ESP.pdf | D9: Spain | E9: A1-A3 | F9: m2 | G9: 7.65 | H9: 2025
A10: AENOR | B10: Ceramic tiles, tiles | C10: https://www.en.aenor.com/Producto_DAP_pdf/GlobalEPD_002_016_ESP.pdf | D10: Spain | E10: A1-A3 | F10: m2 | G10: 9.28 | H10: 2025
A11: AENOR | B11: Ceramic tiles, porcelain stoneware | C11: https://www.en.aenor.com/Producto_DAP_pdf/GlobalEPD_002_017_r1_ESP.pdf | D11: Spain | E11: A1-A3 | F11: m2 | G11: 9.63 | H11: 2025
A12: AENOR | B12: Ceramic tiles, glazed stoneware | C12: https://www.en.aenor.com/Producto_DAP_pdf/GlobalEPD_002_018_ESP.pdf | D12: Spain | E12: A1-A3 | F12: m2 | G12: 8.8 | H12: 2025
A13: AENOR | B13: Ceramic tiles, glazed stoneware | C13: https://www.en.aenor.com/Producto_DAP_pdf/GlobalEPD_002_019_ESP.pdf | D13: Spain | E13: A1-A3 | F13: m2 | G13: 7.65 | H13: 2025
A14: AENOR | B14: Ceramic tiles, tiles | C14: https://www.en.aenor.com/Producto_DAP_pdf/GlobalEPD_002_020_ESP.pdf | D14: Spain | E14: A1-A3 | F14: m2 | G14: 9.28 | H14: 2025
A15: AENOR | B15: Ceramic tiles, porcelain stoneware | C15: https://www.en.aenor.com/Producto_DAP_pdf/GlobalEPD_002_021_r1_ESP.pdf | D15: Spain | E15: A1-A3 | F15: m2 | G15: 9.63 | H15: 2025
A16: AENOR | B16: Ceramic tiles, glazed stoneware | C16: https://www.en.aenor.com/Producto_DAP_pdf/GlobalEPD_002_022_ESP.pdf | D16: Spain | E16: A1-A3 | F16: m2 | G16: 8.8 | H16: 2025
... A53: EcoPlatform/Environdec | B53: CERAMIC TILES OF MEDIUM SIZE BIa TYPE UNGLAZED Production in Malino | C53: https://data.environdec.com/datasetdetail/process.xhtml?uuid=2609eb24-4ccc-41af-8e0f-3079f619f1e2&version=00.00.033&lang=enn | D53: Russia | E53: A1-A3 | F53: m2 | G53: 13.4 | H53: 2025
A54: EcoPlatform/EPD Italy | B54: Ceramic tiles | C54: https://node.epditaly.it/datasetdetail/process.xhtml?uuid=c749dc16-a727-433d-97cb-57262dd5d87a&version=00.00.026&lang=en | D54: Italy | E54: A1-A3 | F54: m2 | G54: 15.5 | H54: 2024 | I54: applicable to Europe, but production in Italy
A55: EcoPlatform/EPD Italy | B55: Ceramic tiles | C55: https://node.epditaly.it/datasetdetail/process.xhtml?uuid=616ecdaf-7849-4955-a2f8-c213c3324be2&version=00.00.026&lang=en | D55: Italy | E55: A1-A3 | F55: m2 | G55: 9.47 | H55: 2024 | I55: applicable to Europe, but production in Italy
A56: EcoPlatform/EPD Italy | B56: Ceramic tiles | C56: https://node.epditaly.it/datasetdetail/process.xhtml?uuid=eb08b38b-83db-4684-801e-a0299c828fcb&version=00.00.025&lang=en | D56: Italy | E56: A1-A3 | F56: m2 | G56: 17.9 | H56: 2024 | I56: applicable to Europe, but production in Italy
A57: EcoPlatform/EPD Italy | B57: Ceramic tiles | C57: https://node.epditaly.it/datasetdetail/process.xhtml?uuid=a5b30dbe-9b5b-4b73-b28f-86c7a10e6242&version=00.00.026&lang=en | D57: Italy | E57: A1-A3 | F57: m2 | G57: 8.15 | H57: 2024 | I57: applicable to Europe, but production in Italy
A58: EcoPlatform/EPD Italy | B58: Ceramic tiles | C58: https://node.epditaly.it/datasetdetail/process.xhtml?uuid=c1a9158c-d3a9-41f5-b7c2-5fe454e4f014&version=00.00.025&lang=en | D58: Italy | E58: A1-A3 | F58: m2 | G58: 11.7 | H58: 2025 | I58: applicable to Europe, but production in Italy
A59: EcoPlatform/EPD Italy | B59: Porcelain stoneware ceramic tiles | C59: https://node.epditaly.it/datasetdetail/process.xhtml?uuid=9ba3d1db-84fb-4dec-b3b0-af8f3e762539&version=00.00.036&lang=en | D59: Italy | E59: A1-A3 | F59: m2 | G59: 9.35 | H59: 2025 | I59: applicable to Europe, but production in Italy
A60: EcoPlatform/EPD Italy | B60: Ceramic tiles | C60: https://node.epditaly.it/datasetdetail/process.xhtml?uuid=35c5f24a-b935-4441-add2-cef5e1ebf1ac&version=00.00.028&lang=en | D60: Italy | E60: A1-A3 | F60: m2 | G60: 9.3 | H60: 2026 | I60: applicable to Europe, but production in Italy
A61: EcoPlatform/EPD Italy | B61: Ceramic tiles | C61: https://node.epditaly.it/datasetdetail/process.xhtml?uuid=2de55445-2d1d-4037-baa2-110f132c3d9e&version=00.03.000&lang=en | D61: Italy | E61: A1-A3 | F61: m2 | G61: 29.9 | H61: 2026 | I61: slabs 12mm+
A62: EcoPlatform/EPD Italy | B62: Ceramic tiles | C62: https://node.epditaly.it/datasetdetail/process.xhtml?uuid=131ecb28-0bcd-4c5d-8a9a-e2f18a819960&version=00.03.000&lang=en | D62: Italy | E62: A1-A3 | F62: m2 | G62: 48.5 | H62: 2026 | I62: slabs 20mm+
A63: EcoPlatform/EPD Italy | B63: Ceramic tiles | C63: https://node.epditaly.it/datasetdetail/process.xhtml?uuid=73fb6f26-13d7-496c-bc72-eb99fe42528f&version=00.03.000&lang=en | D63: Italy | E63: A1-A3 | F63: m2 | G63: 10.2 | H63: 2026 | I63: 3mm
A64: EcoPlatform/EPD Italy | B64: Ceramic tiles | C64: https://node.epditaly.it/datasetdetail/process.xhtml?uuid=e912eeca-4060-4fe6-8cbb-f35b1272a0a0&version=00.03.000&lang=en | D64: Italy | E64: A1-A3 | F64: m2 | G64: 12.4 | H64: 2026 | I64: 3mm+
A65: EcoPlatform/EPD Italy | B65: Ceramic tiles | C65: https://node.epditaly.it/datasetdetail/process.xhtml?uuid=6746751e-4299-48b2-930c-d5beb7a202e4&version=00.03.000&lang=en | D65: Italy | E65: A1-A3 | F65: m2 | G65: 17 | H65: 2026 | I65: 5mm
A66: EcoPlatform/EPD Italy | B66: Ceramic tiles | C66: https://node.epditaly.it/datasetdetail/process.xhtml?uuid=1d8f36aa-c86c-48ba-90ba-795ed8cbd876&version=00.03.000&lang=en | D66: Italy | E66: A1-A3 | F66: m2 | G66: 19.8 | H66: 2026 | I66: 5mm+
A67: EcoPlatform/IBU | B67: Italian Ceramic Tiles | C67: https://ibudata.lca-data.com/datasetdetail/process.xhtml?uuid=98a6e52b-6e12-4542-afa7-371740748685&version=00.01.000&stock=PUBLIC&lang=en | D67: Italy | E67: A1-A3 | F67: m2 | G67: 11.03 | H67: 2028
A68: EPD International | B68: Stoneware extruded tiles | C68: https://api.environdec.com/api/v1/EPDLibrary/Files/ccef3aaa-c7ac-451c-c264-08da3724454d/Data | D68: Spain | E68: A1-A3 | F68: m2 | G68: 24.9 | H68: 2027
A69: EPD International | B69: Porcelain stoneware tiles | C69: https://api.environdec.com/api/v1/EPDLibrary/Files/08e8581b-33e7-4738-566c-08da12da9675/Data | D69: Spain | E69: A1-A3 | F69: m2 | G69: 10.2 | H69: 2027
A70: EPD International | B70: Glazed stoneware tiles | C70: https://api.environdec.com/api/v1/EPDLibrary/Files/5fce72b4-37f2-4f47-566a-08da12da9675/Data | D70: Spain | E70: A1-A3 | F70: m2 | G70: 9.05 | H70: 2027
A71: EPD LCA database | B71: Ceramic Floor Tiles | C71: https://data.lcadatabase.com/datasetdetail/process.xhtml?uuid=2610f976-9424-4a8c-b92e-10b865781526 | D71: Spain | E71: A1-A3 | F71: m2 | G71: 11.27 | H71: 2024
A72: EPD LCA database | B72: Ceramic Floor Tiles | C72: https://data.lcadatabase.com/datasetdetail/process.xhtml?uuid=52c70755-82ae-4f2e-9df3-d095060e8342 | D72: Spain | E72: A1-A3 | F72: m2 | G72: 11.71 | H72: 2024
A73: EPD LCA database | B73: Ceramic porcelain stoneware tiles | C73: https://data.lcadatabase.com/datasetdetail/process.xhtml?uuid=7fb38fa8-07f8-4d92-a4f6-0f80f22fae85 | D73: Spain | E73: A1-A3 | F73: m2 | G73: 13.1 | H73: 2024
A74: EPD LCA database | B74: Ceramic porcelain stoneware tiles | C74: https://data.lcadatabase.com/datasetdetail/process.xhtml?uuid=f195d9eb-a403-43a2-868b-868bf4b4daed | D74: Spain | E74: A1-A3 | F74: m2 | G74: 9.16 | H74: 2024
A75: EPD LCA database | B75: Ceramic porcelain stoneware tiles | C75: https://data.lcadatabase.com/datasetdetail/process.xhtml?uuid=7303466d-0c5d-45a8-9c7b-d985bc4833b4 | D75: Spain | E75: A1-A3 | F75: m2 | G75: 11.4 | H75: 2024
A76: EPD LCA database | B76: Ceramic porcelain stoneware tiles | C76: https://data.lcadatabase.com/datasetdetail/process.xhtml?uuid=c1ca31e4-fcfc-45b9-bec2-27e398d7412aa | D76: Spain | E76: A1-A3 | F76: m2 | G76: 12.5 | H76: 2024
...

Sheet EU-Lay in tile ceilings
A1: METAL LAY IN TILE CEILINGS
A2: source | B2: product | C2: website | D2: region | E2: modules | F2: unit | G2: kg CO2e/unit | H2: valid until | I2: notes | L2: embodied carbon | M2: unit
A3: EcoPlatform/EPDItaly | B3: Metal ceilings: steel panels and systems | C3: https://node.epditaly.it/datasetdetail/process.xhtml?uuid=3c5bc379-52c4-4c33-92c8-a05ab0762835&version=00.03.000&lang=en | D3: Italy | E3: A1-A3 | F3: m2 | G3: 18.95 | H3: 2026 | I3: steel | K3: average | L3: =AVERAGE(G3:G38) -> 20.108447 | M3: kgCO2e/m2
A4: EcoPlatform/IBU | B4: Galvanized steel suspended ceiling panel | C4: https://ibudata.lca-data.com/datasetdetail/process.xhtml?uuid=db56f54d-1f0e-47a4-9d64-91767b016c91&version=00.01.000&stock=PUBLIC&lang=en | D4: Turkey | E4: A1-A3 | F4: m2 | G4: 18 | H4: 2024 | I4: steel | K4: stdev | L4: =STDEV(G3:G38) -> 7.0161267 | M4: kgCO2e/m2
A5: EcoPlatform/IBU | B5: Mesh Ceiling Membranes (1 mm) | C5: https://ibudata.lca-data.com/datasetdetail/process.xhtml?uuid=f4ed9f09-260c-47f6-9997-b5169adadf03&version=00.05.000&stock=PUBLIC&lang=en | D5: Italy | E5: A1-A3 | F5: m2 | G5: 13.39 | H5: 2027 | I5: steel
A6: EcoPlatform/IBU | B6: Mesh Ceiling Membranes (1.5 mm) | C6: https://ibudata.lca-data.com/datasetdetail/process.xhtml?uuid=092a66fb-611b-479c-b434-5fae1aaabb3e&version=00.05.000&stock=PUBLIC&lang=en | D6: Italy | E6: A1-A3 | F6: m2 | G6: 13.92 | H6: 2027 | I6: steel
A7: EcoPlatform/IBU | B7: Mesh Ceiling Tiles & Panels (1 mm) | C7: https://ibudata.lca-data.com/datasetdetail/process.xhtml?uuid=7eba0cf5-efd0-44c9-bc03-3b5cc304b5f7&version=00.02.000&stock=PUBLIC&lang=en | D7: Italy | E7: A1-A3 | F7: m2 | G7: 13.39 | H7: 2027 | I7: steel
A8: EcoPlatform/IBU | B8: Mesh Ceiling Tiles & Panels (1,5 mm) | C8: https://ibudata.lca-data.com/datasetdetail/process.xhtml?uuid=9a0cee45-9e87-4ebd-ba21-9d47b65dd882&version=00.02.000&stock=PUBLIC&lang=en | D8: Italy | E8: A1-A3 | F8: m2 | G8: 13.92 | H8: 2027 | I8: steel
A9: EcoPlatform/IBU | B9: Metal Ceiling Membranes (0.5 mm, with acoustic fleece) | C9: https://ibudata.lca-data.com/datasetdetail/process.xhtml?uuid=5850e9d0-3454-4ba9-8661-88b465720ed6&version=00.05.000&stock=PUBLIC&lang=en | D9: Europe (Austria, UK) | E9: A1-A3 | F9: m2 | G9: 15.11 | H9: 2027 | I9: steel
A10: EcoPlatform/IBU | B10: Metal Ceiling Membranes (0.5 mm, without acoustic infill) | C10: https://ibudata.lca-data.com/datasetdetail/process.xhtml?uuid=f1671433-b3ff-4932-8168-11c1b5783c6f&version=00.04.000&stock=PUBLIC&lang=en | D10: Europe (Austria, UK) | E10: A1-A3 | F10: m2 | G10: 17.03 | H10: 2027 | I10: steel
A11: EcoPlatform/IBU | B11: Metal Ceiling Membranes (0.6 mm, with acoustic fleece) | C11: https://ibudata.lca-data.com/datasetdetail/process.xhtml?uuid=c30a62cf-8dba-4e73-af10-e23195c93c27&version=00.04.000&stock=PUBLIC&lang=en | D11: Europe (Austria, UK) | E11: A1-A3 | F11: m2 | G11: 19.3 | H11: 2027 | I11: steel
A12: EcoPlatform/IBU | B12: Metal Ceiling Membranes (0.6 mm, without acoustic infill) | C12: https://ibudata.lca-data.com/datasetdetail/process.xhtml?uuid=f56d9fdc-d979-4c70-b81a-e1d8623d8132&version=00.05.000&stock=PUBLIC&lang=en | D12: Europe (Austria, UK) | E12: A1-A3 | F12: m2 | G12: 22.54 | H12: 2027 | I12: steel
A13: EcoPlatform/IBU | B13: Metal Ceiling Membranes (0.7 mm, with acoustic fleece) | C13: https://ibudata.lca-data.com/datasetdetail/process.xhtml?uuid=ffae3994-e0e3-4ef7-9190-624f34b8d971&version=00.05.000&stock=PUBLIC&lang=en | D13: Europe (Austria, UK) | E13: A1-A3 | F13: m2 | G13: 22.07 | H13: 2027 | I13: steel
A14: EcoPlatform/IBU | B14: Metal Ceiling Membranes (0.7 mm, without acoustic infill) | C14: https://ibudata.lca-data.com/datasetdetail/process.xhtml?uuid=59debe2f-35da-4116-8d16-3cb8a1ec1de6&version=00.04.000&stock=PUBLIC&lang=en | D14: Europe (Austria, UK) | E14: A1-A3 | F14: m2 | G14: 25.94 | H14: 2027 | I14: steel
A15: EcoPlatform/IBU | B15: Metal Ceiling Membranes (1 mm, with acoustic fleece) | C15: https://ibudata.lca-data.com/datasetdetail/process.xhtml?uuid=0bab722a-77b2-46e2-a32e-89dd32ffe24e&version=00.06.000&stock=PUBLIC&lang=en | D15: Europe (Austria, UK) | E15: A1-A3 | F15: m2 | G15: 29.63 | H15: 2027 | I15: steel
A16: EcoPlatform/IBU | B16: Metal Ceiling Membranes (1 mm, without acoustic infill) | C16: https://ibudata.lca-data.com/datasetdetail/process.xhtml?uuid=7607c965-2352-4394-9afb-7764538c9be3&version=00.05.000&stock=PUBLIC&lang=en | D16: Europe (Austria, UK) | E16: A1-A3 | F16: m2 | G16: 36.16 | H16: 2027 | I16: steel
... A25: EcoPlatform/IBU | B25: Metal Ceiling Tiles (0.5 mm, without acoustic infill) | C25: https://ibudata.lca-data.com/datasetdetail/process.xhtml?uuid=dc0557ec-f724-4b61-b25d-38665cbad37b&version=00.02.000&stock=PUBLIC&lang=en | D25: Europe (Austria, UK) | E25: A1-A3 | F25: m2 | G25: 17.03 | H25: 2027 | I25: steel
A26: EPD Denmark | B26: Metal ceiling systems made of steel | C26: https://www.epddanmark.dk/media/4y3d0jsw/md-19003-en-dampa-aps-taim-e-v.pdf | D26: Denmark | E26: A1-A3 | F26: m2 | G26: =2.79*6.83 -> 19.0557 | H26: 2024 | I26: steel
A27: EPD International | B27: METAL CEILING SYSTEMS STEEL/ALUMINIUM, SMOOTH/PERFORATED | C27: https://api.environdec.com/api/v1/EPDLibrary/Files/075acc06-3096-494f-932e-db8eb3cf546a/Data | D27: Spain | E27: A1-A3 | F27: m2 | G27: 27 | H27: 2024 | I27: panel Sicilia clip-in, steel
A28: EPD International | B28: METAL CEILING SYSTEMS STEEL/ALUMINIUM, SMOOTH/PERFORATED | C28: https://api.environdec.com/api/v1/EPDLibrary/Files/075acc06-3096-494f-932e-db8eb3cf546a/Data | D28: Spain | E28: A1-A3 | F28: m2 | G28: 27 | H28: 2024 | I28: panel Modena T24, steel
A29: EPD International | B29: METAL CEILING SYSTEMS STEEL/ALUMINIUM, SMOOTH/PERFORATED | C29: https://api.environdec.com/api/v1/EPDLibrary/Files/075acc06-3096-494f-932e-db8eb3cf546a/Data | D29: Spain | E29: A1-A3 | F29: m2 | G29: 24.3 | H29: 2024 | I29: panel Parma T15, steel
A30: EPD International | B30: METAL CEILING SYSTEMS STEEL/ALUMINIUM, SMOOTH/PERFORATED | C30: https://api.environdec.com/api/v1/EPDLibrary/Files/075acc06-3096-494f-932e-db8eb3cf546a/Data | D30: Spain | E30: A1-A3 | F30: m2 | G30: 16.2 | H30: 2024 | I30: panel Roma, steel
A31: EPD International | B31: METAL CEILING SYSTEMS STEEL/ALUMINIUM, SMOOTH/PERFORATED | C31: https://api.environdec.com/api/v1/EPDLibrary/Files/075acc06-3096-494f-932e-db8eb3cf546a/Data | D31: Spain | E31: A1-A3 | F31: m2 | G31: 19.6 | H31: 2024 | I31: panel Murano, steel
A32: EPD International | B32: METAL CEILING SYSTEMS STEEL/ALUMINIUM, SMOOTH/PERFORATED | C32: https://api.environdec.com/api/v1/EPDLibrary/Files/075acc06-3096-494f-932e-db8eb3cf546a/Data | D32: Spain | E32: A1-A3 | F32: m2 | G32: 17.3 | H32: 2024 | I32: panel Capri, steel
A33: EPD International | B33: METAL CEILING SYSTEMS STEEL/ALUMINIUM, SMOOTH/PERFORATED | C33: https://api.environdec.com/api/v1/EPDLibrary/Files/075acc06-3096-494f-932e-db8eb3cf546a/Data | D33: Spain | E33: A1-A3 | F33: m2 | G33: 22 | H33: 2024 | I33: stave Venezia, steel
A34: EPD International | B34: Integra Steel Ceiling System | C34: https://api.environdec.com/api/v1/EPDLibrary/Files/1d3b9fb8-cfbd-4042-530d-08dbd569605a/Dataa | D34: Turkey | E34: A1-A3 | F34: m2 | G34: 4.99 | H34: 2028 | I34: steel
A35: EPD International | B35: FALSE CEILING SYSTEMS AND EXTERNAL CLADDINGS MADE OF STEEL | C35: https://api.environdec.com/api/v1/EPDLibrary/Files/5be3727f-f5e0-4fc0-1669-08da0fd87809/Data | D35: Italy | E35: A1-A3 | F35: m2 | G35: =2.21*5.04 -> 11.1384 | H35: 2026 | I35: steel
A36: INIES | B36: METALLIC CEILING IN POSTLAQUE FOLD BINS (excluding installation accessories) | C36: https://www.base-inies.fr/iniesV4/dist/infos-produit | D36: France | E36: A1-A3 | F36: m2 | G36: 19.6 | H36: 2025 | I36: metal
A37: INIES | B37: METAL CEILING IN PRELAQUES FOLD BINS (excluding installation accessories) | C37: https://www.base-inies.fr/iniesV4/dist/infos-produit | D37: France | E37: A1-A3 | F37: m2 | G37: 15.1 | H37: 2025 | I37: metal
A38: INIES | B38: Gyptone® Activ'Air® Line 6 non-removable decorative and acoustic ceiling system with Isoconfort 35 60 mm | C38: https://www.base-inies.fr/iniesV4/dist/infos-produit | D38: France | E38: A1-A3 | F38: m2 | G38: 6.79 | H38: 2024 | I38: steel

Sheet EU-Raised access floors
A1: METAL LAY IN TILE CEILINGS
A2: source | B2: product | C2: website | D2: region | E2: modules | F2: unit | G2: kg CO2e/unit | H2: valid until | I2: notes | L2: embodied carbon | M2: unit
A3: IBU | B3: Raised Floor System, Type NORTEC | C3: https://www.lindner-group.com/fileadmin/user_upload/intranet/service/green_building/upds/boden/epd-gm-b-001-nortec--en.pdf | D3: Germany | E3: A1-A3 | F3: m2 | G3: 12.6 | H3: 2026 | K3: average | L3: =AVERAGE(G3:G4) -> 21.6 | M3: kgCO2e/m2
A4: EPD International | B4: TARGA RAISED ACCESS FLOORING SYSTEMS –CALCIUM SULPHATE CORE from ASPEN | C4: https://api.environdec.com/api/v1/EPDLibrary/Files/c87447d3-3041-4ccf-5324-08dbd569605a/Data | D4: Turkey | E4: A1-A3 | F4: m2 | G4: 30.6 | H4: 2028 | K4: stdev | L4: =STDEV(G3:G4) -> 12.727922 | M4: kgCO2e/m2

Sheet EU-Piping
A1: PLASTIC PIPES
A2: source | B2: product | C2: application | D2: website | E2: region | F2: modules | G2: unit | H2: kg CO2e/unit | I2: valid until | J2: notes | M2: embodied carbon | N2: unit
A3: AENOR | B3: POLYPROPYLENE (PP-R) AND POLYPROPYLENE WITH GLASS FIBER (PP- R+GF) HOT - COLD WATER PIPELINE SYSTEMS | C3: hot, cold water, heating system | D3: https://www.en.aenor.com/Producto_DAP_pdf/DAP%20Heliroma%20GEPD%20EN15804-016%20Final%20eng.pdf | E3: Spain | F3: A1-A3 | G3: kg | H3: 2.59 | I3: 2027 | J3: PP-R, PP-R+GF | L3: average | M3: =AVERAGE(H3:H149) -> 2.7279607 | N3: kgCO2e/kg
A4: AENOR | B4: MULTILAYER TEMPERATURE RESISTANT POLYETHYLENE (PE-RT) PIPELINE SYSTEMS AND POLYPHENYLSULPHONE (PPSU) FITTINGS FOR HOT - COLD WATER | C4: hot, cold water, heating system | D4: https://www.en.aenor.com/Producto_DAP_pdf/DAP%20Heliroma%20GEPD%20EN15804-017%20Final%20eng.pdf | E4: Spain | F4: A1-A3 | G4: kg | H4: 7.44 | I4: 2027 | J4: PE-RT, PPSU | L4: stdev | M4: =STDEV(H3:H149) -> 2.2174432 | N4: kgCO2e/kg
A5: CO2DATA | B5: Drinking water pipe, PEX | C5: potable water | D5: https://co2data.fi/rakentaminen/#en_id7000000465 | E5: Finland | F5: A1-A3 | G5: kg | H5: 3.93 | I5: - | J5: PEX
A6: EcoPlatform/BRE | B6: 1 m of blue / green pipe S / MF / MF-RP piping system | C6: heating and cooling | D6: https://www.greenbooklive.com/pdfdocs/en15804epd/BREGENEPD000475.pdf | E6: Germany | F6: A1-A3 | G6: kg | H6: =0.99/0.411 -> 2.4087591 | I6: 2028 | J6: PP-R and PP-RCT | L6: acronym | M6: meaning
A7: EcoPlatform/BRE | B7: 1 m of blue / green pipe S / MF / MF-RP piping system | C7: heating and cooling | D7: https://www.greenbooklive.com/pdfdocs/en15804epd/BREGENEPD000478.pdf | E7: Germany | F7: A1-A3 | G7: kg | H7: =4.35/1.568 -> 2.7742347 | I7: 2028 | J7: PP-R and PP-RCT | L7: PP-R/PPRC | M7: polypropylene random copolymer
A8: EcoPlatform/BRE | B8: 1 m of red pipe MF / MF-RP piping system | C8: sprinkler | D8: https://www.greenbooklive.com/pdfdocs/en15804epd/BREGENEPD000476.pdf | E8: Germany | F8: A1-A3 | G8: kg | H8: =1.21/0.294 -> 4.1156463 | I8: 2028 | J8: PP-R and PP-RCT | L8: GF | M8: glass fibers
A9: EcoPlatform/EPD International | B9: LK PAL Universal Pipe A Naked & Pipe in Pipe | C9: heating and cooling, potable water | D9: https://data.environdec.com/datasetdetail/process.xhtml?uuid=dab777c7-2a8e-4ec3-0a1b-08da54e30b17&version=07.00.015&lang=en | E9: Germany | F9: A1-A3 | G9: kg | H9: 8.16 | I9: 2027 | J9: PE-RT, aluminium, PE-RT | L9: PE-RT | M9: polyethylene of raised temperature
A10: EcoPlatform/EPD International | B10: LK PAL Universal Pipe A Naked/Pipe in Pipe/Insulated/Conduit & Insulated | C10: heating and cooling, potable water | D10: https://data.environdec.com/datasetdetail/process.xhtml?uuid=b7ecaeef-6f14-4eea-0a2c-08da54e30b17&version=07.00.015&lang=en | E10: Germany | F10: A1-A3 | G10: kg | H10: 8.16 | I10: 2027 | J10: PE-RT, aluminium, PE-RT | L10: PPSU | M10: polyphenylsulfone
A11: EcoPlatform/EPD International | B11: PPRC Pipes | C11: hot, cold water, heating system | D11: https://data.environdec.com/datasetdetail/process.xhtml?uuid=fbe7c563-55b5-44ac-7277-08da598ce856&version=07.00.015&lang=en | E11: Turkey | F11: A1-A3 | G11: kg | H11: 3.08 | I11: 2027 | J11: PPRC | L11: PP-RCT | M11: polypropylene random copolymer with modified crystallinity and temperature resistance
A12: EcoPlatform/EPD International | B12: Polyethylene Pressure Pipe | C12: hot, cold water, heating system | D12: https://data.environdec.com/datasetdetail/process.xhtml?uuid=d0038193-f540-40a6-72a5-08da598ce856&version=07.00.015&lang=en | E12: Turkey | F12: A1-A3 | G12: kg | H12: 3.23 | I12: 2028 | J12: PE
A13: EcoPlatform/EPD Italy | B13: POLYETHYLENE PIPE FOR WATER, GAS AND INDUSTRIAL APPLICATIONS TYPE “POLIETILENETUBI” | C13: water, gas and industrial fluids under pressure | D13: https://node.epditaly.it/datasetdetail/process.xhtml?uuid=10331b0b-f037-4713-9315-ed8b69e479d4&version=00.03.000&lang=en | E13: Italy | F13: A1-A3 | G13: kg | H13: =456/218 -> 2.0917431 | I13: 2028 | J13: HDPE, 100 m of 110 mm SDR 17 pipe, 218 kg
A14: EcoPlatform/EPD Italy | B14: POLYETHYLENE PIPING SYSTEM FOR WATER, GAS AND INDUSTRIAL APPLICATIONS TYPE “POLIETILENETUBI” AND ELOFIT | C14: water, gas and industrial fluids under pressure | D14: https://node.epditaly.it/datasetdetail/process.xhtml?uuid=0f3ae6eb-563f-471b-810a-a018cec5bc34&version=00.00.028&lang=en | E14: Italy | F14: A1-A3 | G14: kg | H14: =479/218 -> 2.1972477 | I14: 2024 | J14: HDPE, 100 m of 110 mm SDR 17 pipe, 218 kg | L14: HDPE | M14: high-density polyethylene
A15: EcoPlatform/EPD Norge | B15: Flowtite Pressure Pipe FP2.1 with coupling DN450-700, PN1-6, SN5000-10000 | C15: penstocks, pressure mains, water supply, and cooling water | D15: https://epdnorway.lca-data.com/datasetdetail/process.xhtml?uuid=4461c54f-e2ce-4e75-acec-fe8cfa115c8b&version=00.03.001&stock=PUBLIC&lang=en | E15: Europe | F15: A1-A3 | G15: kg | H15: 1.55 | I15: 2026 | J15: polyester resin, sand, glass | L15: PVC | M15: polyvinyl chloride
A16: EcoPlatform/EPD Norge | B16: Flowtite Pressure Pipe FP2.1 with coupling DN800-2000, PN1&6, SN5000&10000 | C16: penstocks, pressure mains, water supply, and cooling water | D16: https://epdnorway.lca-data.com/datasetdetail/process.xhtml?uuid=c38eb024-3489-44d0-97b6-5016fb3566c4&version=00.03.001&stock=PUBLIC&lang=en | E16: Europe | F16: A1-A3 | G16: kg | H16: 1.46 | I16: 2026 | J16: polyester resin, sand, glass | L16: PE | M16: polyethylene
A17: EcoPlatform/EPD Norge | B17: Flowtite Pressure Pipe FP2.1 with coupling DN1200-4000, PN10, SN5000 | C17: penstocks, pressure mains, water supply, and cooling water | D17: https://epdnorway.lca-data.com/datasetdetail/process.xhtml?uuid=c4219f63-44b0-4e42-9a7b-a53d2465c625&version=00.03.001&stock=PUBLIC&lang=en | E17: Europe | F17: A1-A3 | G17: kg | H17: 1.55 | I17: 2026 | J17: polyester resin, sand, glass | L17: PP | M17: polypropylene
A18: EcoPlatform/EPD Norge | B18: Flowtite Pressure Pipe FP2.1 with coupling DN2100-3800, PN1&6, SN5000&10000 | C18: penstocks, pressure mains, water supply, and cooling water | D18: https://epdnorway.lca-data.com/datasetdetail/process.xhtml?uuid=c50fea97-7818-47ce-9281-2cc26014001a&version=00.03.001&stock=PUBLIC&lang=en | E18: Europe | F18: A1-A3 | G18: kg | H18: 1.41 | I18: 2026 | J18: polyester resin, sand, glass | L18: PB | M18: polybutylene
A19: EcoPlatform/EPD Norge | B19: Flowtite Pressure Pipe FP2.1 with coupling DN300-400, PN1-6, SN5000-10000 and DN300-400, PN10, SN10000 | C19: penstocks, pressure mains, water supply, and cooling water | D19: https://epdnorway.lca-data.com/datasetdetail/process.xhtml?uuid=ca9e0e3f-de12-4b27-928c-5803d97bf075&version=00.04.001&stock=PUBLIC&lang=en | E19: Europe | F19: A1-A3 | G19: kg | H19: 1.72 | I19: 2026 | J19: polyester resin, sand, glass | L19: PEX | M19: cross-linked polyethylene
A20: EcoPlatform/EPD Norge | B20: Flowtite Pressure Pipe FP2.1 with coupling DN300-500, PN10, SN5000 | C20: penstocks, pressure mains, water supply, and cooling water | D20: https://epdnorway.lca-data.com/datasetdetail/process.xhtml?uuid=406f7e38-81e9-4cd3-8c02-adcac8c5e45a&version=00.03.001&stock=PUBLIC&lang=en | E20: Europe | F20: A1-A3 | G20: kg | H20: 1.8 | I20: 2026 | J20: polyester resin, sand, glass | L20: GRP | M20: glassfiber reinforced plastic
A21: EcoPlatform/EPD Norge | B21: Flowtite Pressure Pipe FP2.1 with coupling DN300-500, PN16, SN5000 | C21: penstocks, pressure mains, water supply, and cooling water | D21: https://epdnorway.lca-data.com/datasetdetail/process.xhtml?uuid=f84120c0-dadb-4a5f-bcdc-c483c9ec9ff9&version=00.03.001&stock=PUBLIC&lang=en | E21: Europe | F21: A1-A3 | G21: kg | H21: 2.18 | I21: 2026 | J21: polyester resin, sand, glass | L21: ABS | M21: acrylonitrile Butadiene Styrene
A22: EcoPlatform/EPD Norge | B22: Flowtite Pressure Pipe FP2.1 with coupling DN300-600, PN16, SN10000 | C22: penstocks, pressure mains, water supply, and cooling water | D22: https://epdnorway.lca-data.com/datasetdetail/process.xhtml?uuid=7ee6ad88-039b-466b-b819-682a1982ba72&version=00.03.001&stock=PUBLIC&lang=en | E22: Europe | F22: A1-A3 | G22: kg | H22: 1.88 | I22: 2026 | J22: polyester resin, sand, glass | L22: GFK/GFRP | M22: glass-fiber reinforced plastic
A23: EcoPlatform/EPD Norge | B23: Flowtite Pressure Pipe FP2.1 with coupling DN450-600, PN10, SN10000 | C23: penstocks, pressure mains, water supply, and cooling water | D23: https://epdnorway.lca-data.com/datasetdetail/process.xhtml?uuid=592da8b5-de5c-488e-8e2d-bf123945b5bc&version=00.03.001&stock=PUBLIC&lang=en | E23: Europe | F23: A1-A3 | G23: kg | H23: 1.58 | I23: 2026 | J23: polyester resin, sand, glass
A24: EcoPlatform/EPD Norge | B24: Flowtite Pressure Pipe FP2.1 with coupling DN600-1200, PN10, SN5000 | C24: penstocks, pressure mains, water supply, and cooling water | D24: https://epdnorway.lca-data.com/datasetdetail/process.xhtml?uuid=1e35d067-7242-423a-af8a-d718df8783ee&version=00.03.001&stock=PUBLIC&lang=en | E24: Europe | F24: A1-A3 | G24: kg | H24: 1.637 | I24: 2026 | J24: polyester resin, sand, glass
A25: EcoPlatform/EPD Norge | B25: Flowtite Pressure Pipe FP2.1 with coupling DN600-3400, PN16, SN5000 | C25: penstocks, pressure mains, water supply, and cooling water | D25: https://epdnorway.lca-data.com/datasetdetail/process.xhtml?uuid=8bab6010-5d46-472f-a28c-a676ce7ebeb4&version=00.03.001&stock=PUBLIC&lang=en | E25: Europe | F25: A1-A3 | G25: kg | H25: 2.023 | I25: 2026 | J25: polyester resin, sand, glass
A26: EcoPlatform/EPD Norge | B26: Flowtite Pressure Pipe FP2.1 with coupling DN700-3400, PN10, SN10000 | C26: penstocks, pressure mains, water supply, and cooling water | D26: https://epdnorway.lca-data.com/datasetdetail/process.xhtml?uuid=091ee3ff-7a67-405a-8060-22f1a0ef89d9&version=00.03.001&stock=PUBLIC&lang=enn | E26: Europe | F26: A1-A3 | G26: kg | H26: 1.429 | I26: 2026 | J26: polyester resin, sand, glass
A27: EcoPlatform/EPD Norge | B27: Flowtite Pressure Pipe FP2.1 with coupling DN700-3400, PN16, SN10000 | C27: penstocks, pressure mains, water supply, and cooling water | D27: https://epdnorway.lca-data.com/datasetdetail/process.xhtml?uuid=a1272267-206a-4b63-989a-afb6ea749e8a&version=00.03.001&stock=PUBLIC&lang=en | E27: Europe | F27: A1-A3 | G27: kg | H27: 1.724 | I27: 2026 | J27: polyester resin, sand, glass
A28: EcoPlatform/EPD Norge | B28: Flowtite Pressure Pipe FP2.1 with coupling DN500-3400, PN16, SN10000 | C28: penstocks, pressure mains, water supply, and cooling water | D28: https://epdnorway.lca-data.com/datasetdetail/process.xhtml?uuid=b4b0f338-3d4e-4a11-85c9-5b87db51dad1&version=00.03.001&stock=PUBLIC&lang=en | E28: Europe | F28: A1-A3 | G28: kg | H28: 1.683 | I28: 2027 | J28: polyester resin, sand, glass
A29: EcoPlatform/EPD Norge | B29: Hobas Pressure Pipe, Filled (VO), Spigot coupling DN700-3600, PN6, SN20000 | C29: pressure pipe | D29: https://epdnorway.lca-data.com/datasetdetail/process.xhtml?uuid=3354417f-b980-48ec-9db1-30e1cd018645&version=00.03.001&stock=PUBLIC&lang=en | E29: Europe | F29: A1-A3 | G29: kg | H29: 1.42 | I29: 2027 | J29: polyester resin, sand, glass
A30: EcoPlatform/EPD Norge | B30: Hobas Pressure Pipe, Unfilled (RO), Spigot-Coupling, DN1800-3600, PN6, SN12500-30000 | C30: pressure pipe | D30: https://epdnorway.lca-data.com/datasetdetail/process.xhtml?uuid=be2d5880-f014-4a47-a771-927a24a1ca54&version=00.03.001&stock=PUBLIC&lang=en | E30: Europe | F30: A1-A3 | G30: kg | H30: 1.634 | I30: 2027 | J30: polyester resin, sand, glass
A31: EcoPlatform/EPD Norge | B31: Pipe Pressure Hobas, Spigot-Coupling DN200, PN2-8, SN10000-16000 | C31: pressure pipe | D31: https://epdnorway.lca-data.com/datasetdetail/process.xhtml?uuid=45c4fa61-ef08-4cec-907d-85c1ff72d658&version=00.03.001&stock=PUBLIC&lang=en | E31: Europe | F31: A1-A3 | G31: kg | H31: 2.163 | I31: 2027 | J31: polyester resin, sand, glass
A32: EcoPlatform/EPD Norge | B32: Pipe Pressure Hobas, Spigot-Coupling DN500-3600, PN6, SN10000 | C32: pressure pipe | D32: https://epdnorway.lca-data.com/datasetdetail/process.xhtml?uuid=298d39f6-da28-44f8-873c-64db25ae4f43&version=00.03.001&stock=PUBLIC&lang=en | E32: Europe | F32: A1-A3 | G32: kg | H32: 1.548 | I32: 2027 | J32: polyester resin, sand, glass
A33: EcoPlatform/EPD Norge | B33: PE100 RC Pressure pipes SDR 17 | C33: pressure pipe, water supply | D33: https://epdnorway.lca-data.com/resource/datastocks/91413340-7bf0-4f88-a952-0f91cba685df/processes/d67ebaea-c946-4b4e-923b-708daece32be/epd?version=00.03.000 | E33: Denmark | F33: A1-A3 | G33: kg | H33: 2.23 | I33: 2028 | J33: HDPE
A34: EcoPlatform/EPD Norge | B34: PE100 RC Water Pressure pipes SDR 11 | C34: pressure pipe, water supply | D34: https://epdnorway.lca-data.com/resource/datastocks/91413340-7bf0-4f88-a952-0f91cba685df/processes/dfd03514-38a2-4e5a-95c1-b625eb1d4144/epd?version=00.03.000 | E34: Sweden | F34: A1-A3 | G34: kg | H34: 2.23 | I34: 2028 | J34: HDPE
... A38: EPD Norge | B38: PP Nordic Pipe | C38: soil, waste | D38: https://epdnorway.lca-data.com/datasetdetail/process.xhtml?uuid=ed7f7acd-bb3a-4f99-80ba-f70274c5e2b7&version=00.04.000&stock=PUBLIC&lang=en | E38: Sweden | F38: A1-A3 | G38: kg | H38: 2.247 | I38: 2028 | J38: PP
A39: EPD Norge | B39: Flowtite Sewer Pipe FS3.0 with coupling DN300, PN1, SN10000 | C39: acid resistance, sewer and storm water applications | D39: https://www.epd-norge.no/getfile.php/1321651-1637062227/EPDer/Byggevarer/Rørsystemer/NEPD-3245-1868_Flowtite-Sewer-Pipe-FS30-with-coupling---DN300--PN1--SN10000.pdf | E39: Europe | F39: A1-A3 | G39: kg | H39: =22.3/16.1 -> 1.3850932 | I39: 2026 | J39: polyester resin, sand, glass
A40: EPD Norge | B40: Flowtite Sewer Pipe FS3.0 with coupling DN350-700, PN1, SN10000 | C40: acid resistance, sewer and storm water applications | D40: https://www.epd-norge.no/getfile.php/1321645-1637062113/EPDer/Byggevarer/Rørsystemer/NEPD-3244-1869_Flowtite-Sewer-Pipe-FS30-with-coupling---DN350-700--PN1--SN10000.pdf | E40: Europe | F40: A1-A3 | G40: kg | H40: 1.41 | I40: 2026 | J40: polyester resin, sand, glass
A41: EPD Norge | B41: Flowtite Sewer Pipe FS3.0 with coupling DN800-2400, PN1, SN10000 | C41: acid resistance, sewer and storm water applications | D41: https://www.epd-norge.no/getfile.php/1321618-1637061283/EPDer/Byggevarer/Rørsystemer/NEPD-3240-1866_Flowtite-Sewer-Pipe-FS30-with-coupling---DN800-2400--PN1--SN10000.pdf | E41: Europe | F41: A1-A3 | G41: kg | H41: 1.27 | I41: 2026 | J41: polyester resin, sand, glass
A42: EPD Norge | B42: Flowtite Sewer Pipe FS3.0 with coupling DN800-3000, PN1, SN2500 & 5000 | C42: acid resistance, sewer and storm water applications | D42: https://www.epd-norge.no/getfile.php/1321612-1637061139/EPDer/Byggevarer/Rørsystemer/NEPD-3239-1873_Flowtite-Sewer-Pipe-FS30-with-coupling---DN800-3000--PN1--SN2500---5000.pdf | E42: Europe | F42: A1-A3 | G42: kg | H42: 1.34 | I42: 2026 | J42: polyester resin, sand, glass
A43: EPD Norge | B43: Hobas Pipe Sewer, Spigot-Coupling DN500-750, PN1 SN5000 | C43: acid resistance, sewer, drainage and storm water applications | D43: https://www.epd-norge.no/getfile.php/1322953-1646322771/EPDer/Byggevarer/Rørsystemer/NEPD-3384-2005_Hobas-Pipe-Sewer--Spigot-Coupling---DN500-750--PN1-SN5000.pdf | E43: Europe | F43: A1-A3 | G43: kg | H43: 1.55 | I43: 2027 | J43: polyester resin, sand, glass
...

